Traceback (most recent call last):
  File "/home/yhuang5/.local/lib/python3.6/site-packages/pandas/core/indexes/base.py", line 2895, in get_loc
    return self._engine.get_loc(casted_key)
  File "pandas/_libs/index.pyx", line 70, in pandas._libs.index.IndexEngine.get_loc
  File "pandas/_libs/index.pyx", line 101, in pandas._libs.index.IndexEngine.get_loc
  File "pandas/_libs/hashtable_class_helper.pxi", line 1675, in pandas._libs.hashtable.PyObjectHashTable.get_item
  File "pandas/_libs/hashtable_class_helper.pxi", line 1683, in pandas._libs.hashtable.PyObjectHashTable.get_item
KeyError: 'CDR3a'

The above exception was the direct cause of the following exception:

Traceback (most recent call last):
  File "main.py", line 191, in <module>
    "cpu"), cdr3b_col='CDR3b', cdr3a_col='CDR3a', gt_col='binder').scaler
  File "/home/yhuang5/vibtcr/vibtcr/vibtcr/dataset.py", line 90, in __init__
    self.cdr3a = utils.encode_aa_seqs(df[cdr3a_col], utils.blosum50_20aa, self.get_max_aa_len(cdr3a_col))
  File "/home/yhuang5/.local/lib/python3.6/site-packages/pandas/core/frame.py", line 2906, in __getitem__
    indexer = self.columns.get_loc(key)
  File "/home/yhuang5/.local/lib/python3.6/site-packages/pandas/core/indexes/base.py", line 2897, in get_loc
    raise KeyError(key) from err
KeyError: 'CDR3a'
